<mujoco model="myrobot">
  <compiler angle="radian" meshdir="assets" autolimits="true"/>

  <default>
    <default class="leg_motor">     <!-- 3025 -->
      <joint damping="0.12" armature="0.00343" frictionloss="0.032"/>  
    </default>
    <default class="ankle_motor">   <!-- 3045 -->
      <joint damping="0.123" armature="0.00262" frictionloss="0.0076"/>
    </default>
    <default class="head_motor">    <!-- 3032 -->
      <joint damping="0.064" armature="0.001" frictionloss="0.007"/>
    </default>
    <default class="waist_motor">   <!-- 3235 -->
      <joint damping="1.48" armature="0.02262" frictionloss="0.09"/>
    </default>
  </default>


  <asset>
    <mesh name="base_link" file="base_link.stl"/>
    <mesh name="right_hip_pitch_link" file="right_hip_pitch_link.stl"/>
    <mesh name="right_hip_roll_link" file="right_hip_roll_link.stl"/>
    <mesh name="right_hip_yaw_link" file="right_hip_yaw_link.stl"/>
    <mesh name="right_knee_link" file="right_knee_link.stl"/>
    <mesh name="right_ankle_pitch_link" file="right_ankle_pitch_link.stl"/>
    <mesh name="right_ankle_roll_link" file="right_ankle_roll_link.stl"/>
    <mesh name="left_hip_pitch_link" file="left_hip_pitch_link.stl"/>
    <mesh name="left_hip_roll_link" file="left_hip_roll_link.stl"/>
    <mesh name="left_hip_yaw_link" file="left_hip_yaw_link.stl"/>
    <mesh name="left_knee_link" file="left_knee_link.stl"/>
    <mesh name="left_ankle_pitch_link" file="left_ankle_pitch_link.stl"/>
    <mesh name="left_ankle_roll_link" file="left_ankle_roll_link.stl"/>
    <mesh name="waist_pitch_link" file="waist_pitch_link.stl"/>
    <mesh name="waist_yaw_link" content_type="model/stl" file="waist_yaw_link.stl"/>
    <mesh name="right_shoulder_pitch_link" file="right_shoulder_pitch_link.stl"/>
    <mesh name="right_shoulder_roll_link" content_type="model/stl" file="right_shoulder_roll_link.stl"/>
    <mesh name="right_elbow_link" content_type="model/stl" file="right_elbow_link.stl"/>
    <mesh name="left_shoulder_pitch_link" file="left_shoulder_pitch_link.stl"/>
    <mesh name="left_shoulder_roll_link" content_type="model/stl" file="left_shoulder_roll_link.stl"/>
    <mesh name="left_elbow_link" content_type="model/stl" file="left_elbow_link.stl"/>
    <mesh name="head_Link" content_type="model/stl" file="head_Link.stl"/>
  </asset>

  <worldbody>
    <body name="base_link" pos="0 0 0.25">  <site name="imu" size="0.01" pos="0.0086455 0.001 0.016087" />  
      <inertial pos="0.0086455 -0.000070328 0.016087" mass="0.24381" fullinertia="0.000183 0.000161 0.000108 0 0.000006 0" />  
      <freejoint name="floating_base_joint" />
      <geom type="mesh" contype="0" conaffinity="0" group="1" density="0" rgba="0.75294 0.75294 0.75294 1" mesh="base_link"/>
      <geom name="base_collision" size="0.025 0.02 0.05" pos="0.005 0 0.04" type="box" rgba="0.75294 0.75294 0.75294 1"/>
      <body name="right_hip_pitch_link" pos="0 -0.0255 0">
        <inertial pos="0.0072235 -0.022121 0.0090332" quat="0.410677 -0.332457 -0.161329 0.833541" mass="0.12008" diaginertia="4.21805e-05 3.63337e-05 2.04858e-05"/>
        <joint name="right_hip_pitch" pos="0 0 0" axis="0 1 0" range="-1.5 1.2" actuatorfrcrange="-1.96 1.96" class="leg_motor" />
        <geom type="mesh" contype="0" conaffinity="0" group="1" density="0" rgba="0.75294 0.75294 0.75294 1" mesh="right_hip_pitch_link"/>
        <body name="right_hip_roll_link" pos="0 -0.025051 0">
          <inertial pos="0.0089238 -0.00087248 -0.044521" quat="0.692994 -0.119703 0.0721478 0.707266" mass="0.12745" diaginertia="7.57967e-05 5.1064e-05 3.71393e-05"/>
          <joint name="right_hip_roll" pos="0 0 0" axis="1 0 0" range="-0.5 0.5" actuatorfrcrange="-1.96 1.96" class="leg_motor" />
          <geom type="mesh" contype="0" conaffinity="0" group="1" density="0" rgba="0.75294 0.75294 0.75294 1" mesh="right_hip_roll_link"/>
          <geom name="right_hip_roll_collision" size="0.02 0.02 0.025" pos="0.01 0 -0.04" type="box" rgba="0.75294 0.75294 0.75294 1"/>
          <body name="right_hip_yaw_link" pos="0 0 -0.06765">
            <inertial pos="0.0091242 2.0459e-06 -0.021973" quat="0 0.648004 0 0.761637" mass="0.11639" diaginertia="4.03246e-05 3e-05 2.76754e-05"/>
            <joint name="right_hip_yaw" pos="0 0 0" axis="0 0 1" range="-0.6 0.6" actuatorfrcrange="-1.96 1.96" class="leg_motor" />
            <geom type="mesh" contype="0" conaffinity="0" group="1" density="0" rgba="0.75294 0.75294 0.75294 1" mesh="right_hip_yaw_link"/>
            <body name="right_knee_link" pos="0 0 -0.024275">
              <inertial pos="0.0003913 0.0032838 -0.052807" quat="0.998066 -0.061928 -0.00491804 -0.00241589" mass="0.14889" diaginertia="0.00015701 0.000134245 5.27444e-05"/>
              <joint name="right_knee" pos="0 0 0" axis="0 1 0" range="-0.2 1.8" actuatorfrcrange="-1.96 1.96"  class="leg_motor" />
              <geom type="mesh" contype="0" conaffinity="0" group="1" density="0" rgba="0.75294 0.75294 0.75294 1" mesh="right_knee_link"/>
              <geom name="right_knee_collision" size="0.005 0.005 0.06" pos="0.002 0.007 -0.05" type="box" rgba="0.75294 0.75294 0.75294 1"/>
              <body name="right_ankle_pitch_link" pos="0 0 -0.1034">
                <inertial pos="0.00025641 0.002877 0.0055643" quat="0.69352 -0.13795 0.13795 0.69352" mass="0.049665" diaginertia="1.04142e-05 9e-06 7.58579e-06"/>
                <joint name="right_ankle_pitch" pos="0 0 0" axis="0 1 0" range="-0.8 0.8" actuatorfrcrange="-2.942 2.942" class="ankle_motor" />
                <geom type="mesh" contype="0" conaffinity="0" group="1" density="0" rgba="0.75294 0.75294 0.75294 1" mesh="right_ankle_pitch_link"/>
                <body name="right_ankle_roll_link">
                  <site name="right_foot" rgba="1 0 0 1" pos="0.005 0 -0.04"/>
                  <inertial pos="0.0015463 3.139e-05 -0.0308" quat="0.415559 0.572111 0.572111 0.415559" mass="0.046131" diaginertia="3.3e-05 3.03007e-05 1.66993e-05"/>
                  <joint name="right_ankle_roll" pos="0 0 0" axis="1 0 0" range="-0.4 0.4" actuatorfrcrange="-2.942 2.942" class="ankle_motor"/>
                  <geom type="mesh" contype="0" conaffinity="0" group="1" density="0" rgba="0.75294 0.75294 0.75294 1" mesh="right_ankle_roll_link"/>
                  <geom name="r_foot_1_collision" type="cylinder" size="0.007 0.035" pos="0.005 0.011 -0.04" quat="0.707107 0 0.707107 0" rgba="0.75294 0.75294 0.75294 1" friction="0.9 0.005 0.0001"/>
                  <geom name="r_foot_2_collision" type="cylinder" size="0.007 0.035" pos="0.005 -0.011 -0.04" quat="0.707107 0 0.707107 0" rgba="0.75294 0.75294 0.75294 1" friction="0.9 0.005 0.0001"/>
                </body>
              </body>
            </body>
          </body>
        </body>
      </body>
      <body name="left_hip_pitch_link" pos="0 0.0246 0">
        <inertial pos="0.0072614 0.023035 0.0090137" quat="0.765406 -0.109271 -0.203512 0.600663" mass="0.12003" diaginertia="4.07798e-05 2.98888e-05 2.83314e-05"/>
        <joint name="left_hip_pitch" pos="0 0 0" axis="0 1 0" range="-1.5 1.2" actuatorfrcrange="-1.96 1.96" class="leg_motor" />
        <geom type="mesh" contype="0" conaffinity="0" group="1" density="0" rgba="0.75294 0.75294 0.75294 1" mesh="left_hip_pitch_link"/>
        <body name="left_hip_roll_link" pos="0 0.025951 0">
          <inertial pos="0.0089461 0.00088223 -0.04455" quat="0.707282 -0.0209903 -0.0423551 0.70535" mass="0.12748" diaginertia="7.30303e-05 5.10898e-05 3.98799e-05"/>
          <joint name="left_hip_roll" pos="0 0 0" axis="1 0 0" range="-0.5 0.5" actuatorfrcrange="-1.96 1.96" class="leg_motor" />
          <geom type="mesh" contype="0" conaffinity="0" group="1" density="0" rgba="0.75294 0.75294 0.75294 1" mesh="left_hip_roll_link"/>
          <geom name="left_hip_roll_collision" size="0.02 0.02 0.025" pos="0.01 0 -0.04" type="box" rgba="0.75294 0.75294 0.75294 1"/>
          <body name="left_hip_yaw_link" pos="0 0 -0.0722">
            <inertial pos="0.009124 -1.5534e-06 -0.017423" quat="0 0.648004 0 0.761637" mass="0.11639" diaginertia="4.03246e-05 3e-05 2.76754e-05"/>
            <joint name="left_hip_yaw" pos="0 0 0" axis="0 0 1" range="-0.6 0.6" actuatorfrcrange="-1.96 1.96" class="leg_motor" />
            <geom type="mesh" contype="0" conaffinity="0" group="1" density="0" rgba="0.75294 0.75294 0.75294 1" mesh="left_hip_yaw_link"/>
            <body name="left_knee_link" pos="0 0 -0.019725">
              <inertial pos="0.00039184 -0.0033037 -0.052775" quat="0.998066 0.061928 -0.00491804 0.00241589" mass="0.14881" diaginertia="0.00015701 0.000134245 5.27444e-05"/>
              <joint name="left_knee" pos="0 0 0" axis="0 1 0" range="-0.2 1.8" actuatorfrcrange="-1.96 1.96" class="leg_motor" />
              <geom type="mesh" contype="0" conaffinity="0" group="1" density="0" rgba="0.75294 0.75294 0.75294 1" mesh="left_knee_link"/>
              <geom name="left_knee_collision" size="0.005 0.005 0.06" pos="0.002 -0.007 -0.05" type="box" rgba="0.75294 0.75294 0.75294 1"/>
              <body name="left_ankle_pitch_link" pos="0 0 -0.1034">
                <inertial pos="0.00025488 -0.0028766 0.005565" quat="0.69352 0.13795 -0.13795 0.69352" mass="0.049659" diaginertia="1.04142e-05 9e-06 7.58579e-06"/>
                <joint name="left_ankle_pitch" pos="0 0 0" axis="0 1 0" range="-0.8 0.8" actuatorfrcrange="-2.942 2.942" class="ankle_motor"/>
                <geom type="mesh" contype="0" conaffinity="0" group="1" density="0" rgba="0.75294 0.75294 0.75294 1" mesh="left_ankle_pitch_link"/>
                <body name="left_ankle_roll_link">
                  <site name="left_foot" rgba="1 0 0 1" pos="0.005 0 -0.04"/>
                  <inertial pos="0.0015451 -3.2861e-05 -0.030801" quat="0.415559 0.572111 0.572111 0.415559" mass="0.046134" diaginertia="3.3e-05 3.03007e-05 1.66993e-05"/>
                  <joint name="left_ankle_roll" pos="0 0 0" axis="1 0 0" range="-0.4 0.4" actuatorfrcrange="-2.942 2.942" class="ankle_motor"/>
                  <geom type="mesh" contype="0" conaffinity="0" group="1" density="0" rgba="0.75294 0.75294 0.75294 1" mesh="left_ankle_roll_link"/>
                  <geom name="l_foot_1_collision" type="cylinder" size="0.007 0.035" pos="0.005 -0.011 -0.04" quat="0.707107 0 0.707107 0" rgba="0.75294 0.75294 0.75294 1" friction="0.9 0.005 0.0001"/>
                  <geom name="l_foot_2_collision" type="cylinder" size="0.007 0.035" pos="0.005 0.011 -0.04" quat="0.707107 0 0.707107 0" rgba="0.75294 0.75294 0.75294 1" friction="0.9 0.005 0.0001"/>
                </body>
              </body>
            </body>
          </body>
        </body>
      </body>
      <body name="waist_pitch_link" pos="0.01 0 0.069">
        <inertial pos="-0.011932 -0.00019894 0.0025083" quat="0.458208 0.538559 0.538559 0.458208" mass="0.1034" diaginertia="3e-05 2.93246e-05 1.66754e-05"/>
        <joint name="waist_pitch" pos="0 0 0" axis="0 1 0" range="-0.8 0.8" actuatorfrcrange="-2.94 2.94" class="waist_motor"/>
        <geom type="mesh" contype="0" conaffinity="0" group="1" density="0" rgba="0.75294 0.75294 0.75294 1" mesh="waist_pitch_link"/>
        <body name="waist_yaw_link">
          <inertial pos="-0.010109 7.0289e-06 0.063605" quat="0.705893 0.707601 -0.0225561 0.022519" mass="0.62386" diaginertia="0.000968319 0.000889683 0.000475998"/>
          <joint name="waist_yaw" pos="0 0 0" axis="0 0 1" range="-0.8 0.8" actuatorfrcrange="-2.94 2.94" class="waist_motor"/>
          <geom type="mesh" contype="0" conaffinity="0" group="1" density="0" rgba="0.75294 0.75294 0.75294 1" mesh="waist_yaw_link"/>
          <geom name="waist_yaw_collision" size="0.025 0.05 0.025" pos="0 0 0.06" type="box" rgba="0.75294 0.75294 0.75294 1"/>
          <body name="right_shoulder_pitch_link" pos="0 0.09 0.07826">
            <inertial pos="0.00020277 -0.16696 2.6745e-05" quat="0 0.707107 0 0.707107" mass="0.02394" diaginertia="1.1e-05 9e-06 5e-06"/>
            <joint name="right_shoulder_pitch" pos="0 0 0" axis="0 1 0" range="-0.8 0.8" actuatorfrcrange="-1.96 1.96" class="leg_motor"/>
            <geom type="mesh" contype="0" conaffinity="0" group="1" density="0" rgba="0.75294 0.75294 0.75294 1" mesh="right_shoulder_pitch_link"/>
            <body name="right_shoulder_roll_link" pos="0 -0.18 0" quat="0.988771 -0.149438 0 0">
              <inertial pos="-0.0002677 5.7571e-05 -0.028251" quat="0.707107 0 0 0.707107" mass="0.10544" diaginertia="8.9e-05 8.6e-05 1.9e-05"/>
              <joint name="right_shoulder_roll" pos="0 0 0" axis="1 0 0" range="-0.8 0.8" actuatorfrcrange="-2.942 2.942"  class="waist_motor"/>
              <geom type="mesh" contype="0" conaffinity="0" group="1" density="0" rgba="0.75294 0.75294 0.75294 1" mesh="right_shoulder_roll_link"/>
              <geom size="0.012 0.02" pos="0 0 -0.025" type="cylinder" rgba="0.75294 0.75294 0.75294 1"/>
              <body name="right_elbow_link" pos="0 0 -0.07">
                <inertial pos="0.00032502 3.9383e-05 -0.030193" quat="0.707107 0 0 0.707107" mass="0.021804" diaginertia="1.6e-05 1.4e-05 6e-06"/>
                <joint name="right_elbow" pos="0 0 0" axis="1 0 0" range="-0.8 0.8" actuatorfrcrange="-0.441 0.441" class="head_motor"/>
                <geom type="mesh" contype="0" conaffinity="0" group="1" density="0" rgba="0.75294 0.75294 0.75294 1" mesh="right_elbow_link"/>
                <geom size="0.012 0.02" pos="0 0 -0.03" type="cylinder" rgba="0.75294 0.75294 0.75294 1"/>
              </body>
            </body>
          </body>
          <body name="left_shoulder_pitch_link" pos="0 -0.061 0.07826">
            <inertial pos="6.783e-05 0.13665 1.6441e-05" quat="0 0.707107 0 0.707107" mass="0.016394" diaginertia="7e-06 5e-06 3e-06"/>
            <joint name="left_shoulder_pitch" pos="0 0 0" axis="0 1 0" range="-0.8 0.8" actuatorfrcrange="-1.96 1.96" class="leg_motor"/>
            <geom type="mesh" contype="0" conaffinity="0" group="1" density="0" rgba="0.75294 0.75294 0.75294 1" mesh="left_shoulder_pitch_link"/>
            <body name="left_shoulder_roll_link" pos="0 0.151 0" quat="0.988771 0.149438 0 0">
              <inertial pos="-0.00026756 -5.7515e-05 -0.02825" quat="0.707107 0 0 0.707107" mass="0.10543" diaginertia="8.9e-05 8.6e-05 1.9e-05"/>
              <joint name="left_shoulder_roll" pos="0 0 0" axis="1 0 0" range="-0.8 0.8" actuatorfrcrange="-2.942 2.942" class="waist_motor"/> 
              <geom type="mesh" contype="0" conaffinity="0" group="1" density="0" rgba="0.75294 0.75294 0.75294 1" mesh="left_shoulder_roll_link"/>
              <geom size="0.01 0.02" pos="0 0 -0.025" type="cylinder" rgba="0.75294 0.75294 0.75294 1"/>
              <body name="left_elbow_link" pos="0 0 -0.07">
                <inertial pos="0.00032614 -3.9103e-05 -0.030193" quat="0.707107 0 0 0.707107" mass="0.021802" diaginertia="1.6e-05 1.4e-05 6e-06"/>
                <joint name="left_elbow" pos="0 0 0" axis="1 0 0" range="-0.8 0.8" actuatorfrcrange="-0.441 0.441" class="head_motor"/>
                <geom type="mesh" contype="0" conaffinity="0" group="1" density="0" rgba="0.75294 0.75294 0.75294 1" mesh="left_elbow_link"/>
                <geom size="0.012 0.02" pos="0 0 -0.03" type="cylinder" rgba="0.75294 0.75294 0.75294 1"/>
              </body>
            </body>
          </body>
          <body name="head_link" pos="0 0 0.10466">
            <inertial pos="0.0013916 -0.00097519 0.041829" mass="0.066764" diaginertia="2.8e-05 2.8e-05 2.5e-05"/>
            <joint name="head" pos="0 0 0" axis="0 0 1" actuatorfrcrange="-0.441 0.441" class="head_motor"/>
            <geom type="mesh" contype="0" conaffinity="0" group="1" density="0" rgba="0.75294 0.75294 0.75294 1" mesh="head_Link"/>
            <geom size="0.021" pos="0 0 0.03" rgba="0.75294 0.75294 0.75294 1"/>
          </body>
        </body>
      </body>
    </body>
  </worldbody>
  <contact>
    <exclude body1="left_shoulder_roll_link" body2="left_elbow_link"/>
    <exclude body1="right_shoulder_roll_link" body2="right_elbow_link"/>
    <exclude body1="base_link" body2="right_hip_pitch_link"/>
    <exclude body1="base_link" body2="left_hip_pitch_link"/>
  </contact>
  <sensor>
    <gyro name="imu_ang_vel" site="imu" />
    <velocimeter name="imu_lin_vel" site="imu" />
    <accelerometer name="imu_lin_acc" site="imu" />
    <framezaxis name="imu_upvector" objtype="body" objname="world" reftype="site" refname="imu"/>
    <subtreeangmom name="root_angmom" body="base_link"/>
  </sensor>
</mujoco>
