<mujoco model="marsdog">
  <compiler angle="radian" balanceinertia="true"/>

  <asset>
    <!-- base_link.STL has 363212 faces (>200000 MuJoCo limit); use primitive geoms on base_link body instead -->
    <mesh name="fl_calf_link" file="/home/elephant/robot/GMR-master/assets/marsdog/meshes/fl_calf_link.STL"/>
    <mesh name="fl_foot_link" file="/home/elephant/robot/GMR-master/assets/marsdog/meshes/fl_foot_link.STL"/>
    <mesh name="fl_hip_pitch_link" file="/home/elephant/robot/GMR-master/assets/marsdog/meshes/fl_hip_pitch_link.STL"/>
    <mesh name="fl_tarsus_link" file="/home/elephant/robot/GMR-master/assets/marsdog/meshes/fl_tarsus_link.STL"/>
    <mesh name="fl_thigh_roll_link" file="/home/elephant/robot/GMR-master/assets/marsdog/meshes/fl_thigh_roll_link.STL"/>
    <mesh name="fr_calf_link" file="/home/elephant/robot/GMR-master/assets/marsdog/meshes/fr_calf_link.STL"/>
    <mesh name="fr_foot_link" file="/home/elephant/robot/GMR-master/assets/marsdog/meshes/fr_foot_link.STL"/>
    <mesh name="fr_hip_pitch_link" file="/home/elephant/robot/GMR-master/assets/marsdog/meshes/fr_hip_pitch_link.STL"/>
    <mesh name="fr_tarsus_link" file="/home/elephant/robot/GMR-master/assets/marsdog/meshes/fr_tarsus_link.STL"/>
    <mesh name="fr_thigh_roll_link" file="/home/elephant/robot/GMR-master/assets/marsdog/meshes/fr_thigh_roll_link.STL"/>
    <mesh name="head_pitch_link" file="/home/elephant/robot/GMR-master/assets/marsdog/meshes/head_pitch_link.STL"/>
    <mesh name="head_roll_link" file="/home/elephant/robot/GMR-master/assets/marsdog/meshes/head_roll_link.STL"/>
    <mesh name="head_yaw_link" file="/home/elephant/robot/GMR-master/assets/marsdog/meshes/head_yaw_link.STL"/>
    <mesh name="imu_link" file="/home/elephant/robot/GMR-master/assets/marsdog/meshes/imu_link.STL"/>
    <mesh name="neck_pitch_link" file="/home/elephant/robot/GMR-master/assets/marsdog/meshes/neck_pitch_link.STL"/>
    <mesh name="rl_calf_link" file="/home/elephant/robot/GMR-master/assets/marsdog/meshes/rl_calf_link.STL"/>
    <mesh name="rl_foot_link" file="/home/elephant/robot/GMR-master/assets/marsdog/meshes/rl_foot_link.STL"/>
    <mesh name="rl_hip_link" file="/home/elephant/robot/GMR-master/assets/marsdog/meshes/rl_hip_link.STL"/>
    <mesh name="rl_tarsus_link" file="/home/elephant/robot/GMR-master/assets/marsdog/meshes/rl_tarsus_link.STL"/>
    <mesh name="rl_thigh_link" file="/home/elephant/robot/GMR-master/assets/marsdog/meshes/rl_thigh_link.STL"/>
    <mesh name="rr_calf_link" file="/home/elephant/robot/GMR-master/assets/marsdog/meshes/rr_calf_link.STL"/>
    <mesh name="rr_foot_link" file="/home/elephant/robot/GMR-master/assets/marsdog/meshes/rr_foot_link.STL"/>
    <mesh name="rr_hip_link" file="/home/elephant/robot/GMR-master/assets/marsdog/meshes/rr_hip_link.STL"/>
    <mesh name="rr_tarsus_link" file="/home/elephant/robot/GMR-master/assets/marsdog/meshes/rr_tarsus_link.STL"/>
    <mesh name="rr_thigh_link" file="/home/elephant/robot/GMR-master/assets/marsdog/meshes/rr_thigh_link.STL"/>
    <mesh name="tail1_link" file="/home/elephant/robot/GMR-master/assets/marsdog/meshes/tail1_link.STL"/>
    <mesh name="tail2_link" file="/home/elephant/robot/GMR-master/assets/marsdog/meshes/tail2_link.STL"/>
    <mesh name="tail3_link" file="/home/elephant/robot/GMR-master/assets/marsdog/meshes/tail3_link.STL"/>
    <mesh name="tail4_link" file="/home/elephant/robot/GMR-master/assets/marsdog/meshes/tail4_link.STL"/>
    <mesh name="tail5_link" file="/home/elephant/robot/GMR-master/assets/marsdog/meshes/tail5_link.STL"/>
    <mesh name="tail6_link" file="/home/elephant/robot/GMR-master/assets/marsdog/meshes/tail6_link.STL"/>
    <mesh name="tail7_link" file="/home/elephant/robot/GMR-master/assets/marsdog/meshes/tail7_link.STL"/>
    <mesh name="tail8_link" file="/home/elephant/robot/GMR-master/assets/marsdog/meshes/tail8_link.STL"/>
    <mesh name="tail9_link" file="/home/elephant/robot/GMR-master/assets/marsdog/meshes/tail9_link.STL"/>
    <mesh name="tail10_link" file="/home/elephant/robot/GMR-master/assets/marsdog/meshes/tail10_link.STL"/>
    <mesh name="tail11_link" file="/home/elephant/robot/GMR-master/assets/marsdog/meshes/tail11_link.STL"/>
    <mesh name="tail12_link" file="/home/elephant/robot/GMR-master/assets/marsdog/meshes/tail12_link.STL"/>
    <mesh name="waist_pitch_link" file="/home/elephant/robot/GMR-master/assets/marsdog/meshes/waist_pitch_link.STL"/>
    <mesh name="waist_roll_link" file="/home/elephant/robot/GMR-master/assets/marsdog/meshes/waist_roll_link.STL"/>
    <mesh name="waist_yaw_link" file="/home/elephant/robot/GMR-master/assets/marsdog/meshes/waist_yaw_link.STL"/>
  </asset>

  <worldbody>
    <body name="base_link" pos="0 0 0">
      <inertial pos="-0.013554 0.000373 0.001080" mass="2.875" fullinertia="0.008005838 0.013668028 0.009240322 0.000066867 -0.000048830 0.003619324"/>
      <freejoint name="base_link"/>
    <geom size="0.032 0.035" pos="-0.021722 0.0335 -0.009186" quat="0.819153 0 0.573574 0" type="cylinder" rgba="0.15 0.15 0.15 1"/>
    <geom size="0.032 0.035" pos="-0.021722 -0.0335 -0.009186" quat="0.819153 0 0.573574 0" type="cylinder" rgba="0.15 0.15 0.15 1"/>
    <geom size="0.0745 0.0325 0.0375" pos="-0.081722 0 0.0462" type="box" rgba="0.15 0.15 0.15 1"/>
    <geom size="0.04 0.025" pos="0.030059 0 0.028279" quat="0.707107 0 0.707107 0" type="cylinder" rgba="0.15 0.15 0.15 1"/>
    <geom size="0.045 0.05 0.03" pos="0.0350059 0 -0.065279" type="box" rgba="0.15 0.15 0.15 1"/>
    <geom pos="0.034059 -0.00020534 -0.015067" quat="1 -0.0006825 0 0" type="mesh" rgba="0.792157 0.819608 0.933333 1" mesh="imu_link"/>
    <body name="tail1_virtual_link" pos="-0.16794 -8.4332e-05 0.033174" quat="0.997564 -0.000117087 -0.0697584 0.000408338">
      <inertial pos="0 0 0" mass="0.0001" diaginertia="1e-09 1e-09 1e-09"/>
      <joint name="tail1_pitch_joint" pos="0 0 0" axis="0 1 0" range="-0.3 0.3" actuatorfrcrange="-6 6"/>
      <body name="tail1_link">
        <inertial pos="-0.00762274 4.59468e-08 8.03589e-09" quat="0.996144 -0.0877366 2.819e-05 2.03761e-05" mass="0.0141852" diaginertia="8.34744e-07 6.99098e-07 6.99051e-07"/>
        <joint name="tail1_yaw_joint" pos="0 0 0" axis="0 0 1" range="-0.3 0.3" actuatorfrcrange="-6 6"/>
        <geom size="0.0112 0.01115" pos="-0.00899 0 0" quat="0.707107 0 0.707107 0" type="cylinder" rgba="0.898039 0.917647 0.929412 1"/>
        <body name="tail2_virtual_link" pos="-0.018124 0 0">
          <inertial pos="0 0 0" mass="0.0001" diaginertia="1e-09 1e-09 1e-09"/>
          <joint name="tail2_pitch_joint" pos="0 0 0" axis="0 1 0" range="-1.0472 1.0472"/>
          <body name="tail2_link">
            <inertial pos="-0.00650946 -1.52171e-09 2.791e-09" quat="0.986326 -0.164804 0 0" mass="0.0127952" diaginertia="7.00744e-07 5.92156e-07 5.9212e-07"/>
            <joint name="tail2_yaw_joint" pos="0 0 0" axis="0 0 1" range="-1.0472 1.0472"/>
            <geom size="0.0108 0.0108" pos="-0.00781 0 0" quat="0.707107 0 0.707107 0" type="cylinder" rgba="0.898039 0.917647 0.929412 1"/>
            <body name="tail3_virtual_link" pos="-0.0167 0 0">
              <inertial pos="0 0 0" mass="0.0001" diaginertia="1e-09 1e-09 1e-09"/>
              <joint name="tail3_pitch_joint" pos="0 0 0" axis="0 1 0" range="-1.0472 1.0472"/>
              <body name="tail3_link">
                <inertial pos="-0.00631417 -4.82119e-08 -7.91466e-08" quat="0.707107 0.707107 6.6426e-06 -2.96929e-05" mass="0.0116836" diaginertia="6.06688e-07 5.1193e-07 5.11929e-07"/>
                <joint name="tail3_yaw_joint" pos="0 0 0" axis="0 0 1" range="-1.0472 1.0472"/>
                <geom size="0.0105 0.0105" pos="-0.00756 0 0" quat="0.707107 0 0.707107 0" type="cylinder" rgba="0.898039 0.917647 0.929412 1"/>
                <body name="tail4_virtual_link" pos="-0.016 0 0">
                  <inertial pos="0 0 0" mass="0.0001" diaginertia="1e-09 1e-09 1e-09"/>
                  <joint name="tail4_pitch_joint" pos="0 0 0" axis="0 1 0" range="-1.0472 1.0472"/>
                  <body name="tail4_link">
                    <inertial pos="-0.00611854 -1.48748e-08 9.01789e-09" quat="0.999413 0.0342531 0 0" mass="0.0106348" diaginertia="5.23075e-07 4.40636e-07 4.40551e-07"/>
                    <joint name="tail4_yaw_joint" pos="0 0 0" axis="0 0 1" range="-1.0472 1.0472"/>
                    <geom size="0.0102 0.0102" pos="-0.00731 0 0" quat="0.707107 0 0.707107 0" type="cylinder" rgba="0.898039 0.917647 0.929412 1"/>
                    <body name="tail5_virtual_link" pos="-0.0157 0 0">
                      <inertial pos="0 0 0" mass="0.0001" diaginertia="1e-09 1e-09 1e-09"/>
                      <joint name="tail5_pitch_joint" pos="0 0 0" axis="0 1 0" range="-1.0472 1.0472"/>
                      <body name="tail5_link">
                        <inertial pos="-0.00590663 -2.33052e-08 -1.20619e-08" quat="0.989288 -0.145974 -9.67359e-07 -6.55593e-06" mass="0.00985156" diaginertia="4.66786e-07 3.89049e-07 3.8903e-07"/>
                        <joint name="tail5_yaw_joint" pos="0 0 0" axis="0 0 1" range="-1.0472 1.0472"/>
                        <geom size="0.01 0.01" pos="-0.00706 0 0" quat="0.707107 0 0.707107 0" type="cylinder" rgba="0.898039 0.917647 0.929412 1"/>
                        <body name="tail6_virtual_link" pos="-0.0152 0 0">
                          <inertial pos="0 0 0" mass="0.0001" diaginertia="1e-09 1e-09 1e-09"/>
                          <joint name="tail6_pitch_joint" pos="0 0 0" axis="0 1 0" range="-1.0472 1.0472"/>
                          <body name="tail6_link">
                            <inertial pos="-0.00569034 5.41745e-09 1.28345e-09" quat="0.988608 -0.150513 -6.81828e-06 1.03807e-06" mass="0.00923075" diaginertia="4.22373e-07 3.47614e-07 3.47596e-07"/>
                            <joint name="tail6_yaw_joint" pos="0 0 0" axis="0 0 1" range="-1.0472 1.0472"/>
                            <geom size="0.0098 0.0098" pos="-0.00681 0 0" quat="0.707107 0 0.707107 0" type="cylinder" rgba="0.898039 0.917647 0.929412 1"/>
                            <body name="tail7_virtual_link" pos="-0.0147 0 0">
                              <inertial pos="0 0 0" mass="0.0001" diaginertia="1e-09 1e-09 1e-09"/>
                              <joint name="tail7_pitch_joint" pos="0 0 0" axis="0 1 0" range="-1.0472 1.0472"/>
                              <body name="tail7_link">
                                <inertial pos="-0.00549512 4.41706e-10 5.92189e-09" quat="0.400611 0.916248 0 0" mass="0.00839276" diaginertia="3.62505e-07 2.97475e-07 2.97467e-07"/>
                                <joint name="tail7_yaw_joint" pos="0 0 0" axis="0 0 1" range="-1.0472 1.0472"/>
                                <geom size="0.0095 0.0095" pos="-0.00656 0 0" quat="0.707107 0 0.707107 0" type="cylinder" rgba="0.898039 0.917647 0.929412 1"/>
                                <body name="tail8_virtual_link" pos="-0.0144 0 0">
                                  <inertial pos="0 0 0" mass="0.0001" diaginertia="1e-09 1e-09 1e-09"/>
                                  <joint name="tail8_pitch_joint" pos="0 0 0" axis="0 1 0" range="-1.0472 1.0472"/>
                                  <body name="tail8_link">
                                    <inertial pos="-0.0056391 4.2088e-08 -1.77923e-08" quat="0.970185 -0.242366 4.58834e-06 1.8367e-05" mass="0.00801678" diaginertia="3.31236e-07 2.79674e-07 2.79661e-07"/>
                                    <joint name="tail8_yaw_joint" pos="0 0 0" axis="0 0 1" range="-1.0472 1.0472"/>
                                    <geom size="0.0092 0.0092" pos="-0.00641 0 0" quat="0.707107 0 0.707107 0" type="cylinder" rgba="0.898039 0.917647 0.929412 1"/>
                                    <body name="tail9_virtual_link" pos="-0.0147 0 0">
                                      <inertial pos="0 0 0" mass="0.0001" diaginertia="1e-09 1e-09 1e-09"/>
                                      <joint name="tail9_pitch_joint" pos="0 0 0" axis="0 1 0" range="-1.0472 1.0472"/>
                                      <body name="tail9_link">
                                        <inertial pos="-0.00551186 -8.70025e-10 -1.17443e-08" quat="0.974352 -0.225029 0 0" mass="0.00782767" diaginertia="3.07e-07 2.66908e-07 2.66902e-07"/>
                                        <joint name="tail9_yaw_joint" pos="0 0 0" axis="0 0 1" range="-1.0472 1.0472"/>
                                        <geom size="0.009 0.00895" pos="-0.00636 0 0" quat="0.707107 0 0.707107 0" type="cylinder" rgba="0.898039 0.917647 0.929412 1"/>
                                        <body name="tail10_virtual_link" pos="-0.0146 0 0">
                                          <inertial pos="0 0 0" mass="0.0001" diaginertia="1e-09 1e-09 1e-09"/>
                                          <joint name="tail10_pitch_joint" pos="0 0 0" axis="0 1 0" range="-1.0472 1.0472"/>
                                          <body name="tail10_link">
                                            <inertial pos="-0.00518801 -1.10406e-08 -2.52233e-08" quat="0.994515 -0.104591 0 0" mass="0.00666178" diaginertia="2.38977e-07 2.06527e-07 2.06521e-07"/>
                                            <joint name="tail10_yaw_joint" pos="0 0 0" axis="0 0 1" range="-1.0472 1.0472"/>
                                            <geom size="0.0086 0.0086" pos="-0.006 0 0" quat="0.707107 0 0.707107 0" type="cylinder" rgba="0.898039 0.917647 0.929412 1"/>
                                            <body name="tail11_virtual_link" pos="-0.0139 0 0">
                                              <inertial pos="0 0 0" mass="0.0001" diaginertia="1e-09 1e-09 1e-09"/>
                                              <joint name="tail11_pitch_joint" pos="0 0 0" axis="0 1 0" range="-1.0472 1.0472"/>
                                              <body name="tail11_link">
                                                <inertial pos="-0.00495916 8.55363e-09 5.3374e-08" quat="0.707107 -1.46685e-05 -1.46685e-05 0.707107" mass="0.00462076" diaginertia="1.46827e-07 1.44478e-07 1.07696e-07"/>
                                                <joint name="tail11_yaw_joint" pos="0 0 0" axis="0 0 1" range="-1.0472 1.0472"/>
                                                <geom size="0.0077 0.0082" pos="-0.00546 0 0" quat="0.707107 0 0.707107 0" type="cylinder" rgba="0.898039 0.917647 0.929412 1"/>
                                                <body name="tail12_virtual_link" pos="-0.011979 0 0">
                                                  <inertial pos="0 0 0" mass="0.0001" diaginertia="1e-09 1e-09 1e-09"/>
                                                  <joint name="tail12_pitch_joint" pos="0 0 0" axis="0 1 0" range="-1.0472 1.0472"/>
                                                  <body name="tail12_link">
                                                    <inertial pos="-0.005915 -2.92924e-07 4.29541e-07" quat="0.991427 -0.130658 0.000222651 0.000175694" mass="0.00556654" diaginertia="1.74072e-07 1.54273e-07 1.54213e-07"/>
                                                    <joint name="tail12_yaw_joint" pos="0 0 0" axis="0 0 1" range="-1.0472 1.0472"/>
                                                    <geom size="0.008 0.008" pos="-0.0065 0 0" quat="0.707107 0 0.707107 0" type="cylinder" rgba="0.898039 0.917647 0.929412 1"/>
                                                  </body>
                                                </body>
                                              </body>
                                            </body>
                                          </body>
                                        </body>
                                      </body>
                                    </body>
                                  </body>
                                </body>
                              </body>
                            </body>
                          </body>
                        </body>
                      </body>
                    </body>
                  </body>
                </body>
              </body>
            </body>
          </body>
        </body>
      </body>
    </body>
    <body name="rl_hip_link" pos="-0.041722 0.0335 -0.015186" quat="0.984807 -0.00067213 -0.17365 0.000118509">
      <inertial pos="-0.045138 0.013793 -1.7e-05" quat="0.569695 0.59045 0.400048 0.408385" mass="0.374" diaginertia="0.000188715 0.000184128 0.0001655"/>
      <joint name="rl_hip_joint" pos="0 0 0" axis="1 -0.00046685 0" range="-0.49 0.77" actuatorfrcrange="-18 18"/>
      <geom size="0.032 0.035" pos="-0.045 0.024 0" quat="0.707107 0.707107 0 0" type="cylinder" rgba="0.898039 0.917647 0.929412 1"/>
      <body name="rl_thigh_link" pos="-0.046282 0.039422 5.0587e-05" quat="0.984807 0 0.17365 0">
        <inertial pos="0.008049 -0.015362 -0.059444" quat="0.992279 -0.0635898 -0.0909617 -0.0553655" mass="0.414" diaginertia="0.000346421 0.00029124 0.00021253"/>
        <joint name="rl_thigh_joint" pos="0 0 0" axis="0 0.999999 0.001365" range="-0.71 1.77" actuatorfrcrange="-14 14"/>
        <geom size="0.03 0.0325" pos="0.008 -0.015 -0.061" quat="0.707107 0.707107 0 0" type="cylinder" rgba="0.898039 0.917647 0.929412 1"/>
        <body name="rl_calf_link" pos="0.023309 0.0090594 -0.11679">
          <inertial pos="-0.018059 -0.003444 -0.027577" quat="0.712636 0.0414986 0.0452216 0.698843" mass="0.048" diaginertia="3.6917e-05 3.56549e-05 5.15408e-06"/>
          <joint name="rl_calf_joint" pos="0 0 0" axis="0 -0.999999 -0.001365" range="-1.56 0" actuatorfrcrange="-14 14"/>
          <geom size="0.0115 0.015 0.0275" pos="-0.019375 5.31e-05 -0.038886" quat="0.0414987 -0.712636 -0.698843 0.0452216" type="box" rgba="0.898039 0.917647 0.929412 1"/>
          <body name="rl_tarsus_link" pos="-0.01875 0.00010616 -0.077772">
            <inertial pos="-0.000531379 0.00914935 -0.0177899" quat="0.946256 -0.291461 -0.139885 0.00913218" mass="0.037" diaginertia="3.96792e-05 2.76035e-05 1.42892e-05"/>
            <joint name="rl_tarsus_joint" pos="0 0 0" axis="0 -0.999999 -0.001365" range="-3.14159 3.14159"/>
            <geom size="0.007 0.01 0.03" pos="0.003795 0.0052055 -0.030978" quat="0.0223342 0.69637 0.701396 0.150376" type="box" rgba="0.898039 0.917647 0.929412 1"/>
            <geom pos="0.01159 0.010411 -0.061956" quat="1 0 0 0" type="mesh" rgba="0.898039 0.917647 0.929412 1" mesh="rl_foot_link"/>
          </body>
        </body>
      </body>
    </body>
    <body name="rr_hip_link" pos="-0.041722 -0.0335 -0.015186" quat="0.984807 -0.00067213 -0.17365 0.000118509">
      <inertial pos="-0.045138 -0.013793 -1.7e-05" quat="0.408385 0.400048 0.59045 0.569695" mass="0.374" diaginertia="0.000188715 0.000184128 0.0001655"/>
      <joint name="rr_hip_joint" pos="0 0 0" axis="1 -0.00046685 0" range="-0.77 0.49" actuatorfrcrange="-18 18"/>
      <geom size="0.032 0.035" pos="-0.045 -0.024 0" quat="0.707107 0.707107 0 0" type="cylinder" rgba="0.898039 0.917647 0.929412 1"/>
      <body name="rr_thigh_link" pos="-0.046318 -0.039378 -5.0537e-05" quat="0.984807 0 0.17365 0">
        <inertial pos="0.008049 0.015362 -0.059444" quat="0.992279 0.0635898 -0.0909617 0.0553655" mass="0.414" diaginertia="0.000346421 0.00029124 0.00021253"/>
        <joint name="rr_thigh_joint" pos="0 0 0" axis="0 -0.999999 -0.001365" range="-1.77 0.71" actuatorfrcrange="-14 14"/>
        <geom size="0.03 0.0325" pos="0.008 0.015 -0.061" quat="0.707107 0.707107 0 0" type="cylinder" rgba="0.898039 0.917647 0.929412 1"/>
        <body name="rr_calf_link" pos="0.022904 -0.0087404 -0.1169">
          <inertial pos="-0.018059 0.003444 -0.027577" quat="0.698843 0.0452216 0.0414986 0.712636" mass="0.048" diaginertia="3.6917e-05 3.56549e-05 5.15408e-06"/>
          <joint name="rr_calf_joint" pos="0 0 0" axis="0 0.999999 0.001365" range="0 1.56" actuatorfrcrange="-14 14"/>
          <geom size="0.0115 0.015 0.0275" pos="-0.019375 -5.31e-05 -0.038886" quat="0.0414987 0.712636 -0.698843 -0.0452216" type="box" rgba="0.898039 0.917647 0.929412 1"/>
          <body name="rr_tarsus_link" pos="-0.019514 0 -0.077584">
            <inertial pos="0.00218455 0.0076047 -0.0171465" quat="0.921716 -0.332012 -0.0945449 -0.17683" mass="0.037" diaginertia="4.13422e-05 3.44325e-05 9.03283e-06"/>
            <joint name="rr_tarsus_joint" pos="0 0 0" axis="0 0.999999 0.001365" range="-3.14159 3.14159"/>
            <geom size="0.007 0.01 0.03" pos="0.003795 -0.0052055 -0.030978" quat="0.0223342 -0.69637 0.701396 -0.150376" type="box" rgba="0.898039 0.917647 0.929412 1"/>
            <geom pos="0.011375 -0.010242 -0.062024" quat="1 0 0 0" type="mesh" rgba="0.898039 0.917647 0.929412 1" mesh="rr_foot_link"/>
          </body>
        </body>
      </body>
    </body>
    <body name="waist_roll_link" pos="0.055059 0 0.028279" quat="1 -0.0006825 0 0">
      <inertial pos="0.039275 -0.004052 0.000334" quat="0.420952 0.636083 -0.175369 0.622449" mass="0.337" diaginertia="0.00019013 0.000185199 0.000173084"/>
      <joint name="waist_roll_joint" pos="0 0 0" axis="1 0 0" range="-1 1" actuatorfrcrange="-17 17"/>
      <geom size="0.03 0.035" pos="0.041 0 0" quat="0.707107 0.707107 0 0" type="cylinder" rgba="0.898039 0.917647 0.929412 1"/>
      <body name="waist_pitch_link" pos="0.0415 0 0">
        <inertial pos="0.056619 -0.000962 -0.039921" quat="0.979591 0.0137013 0.0525858 -0.193517" mass="1.098" diaginertia="0.00227842 0.00217527 0.00135666"/>
        <joint name="waist_pitch_joint" pos="0 0 0" axis="0 0.999999 0.001365" range="0 0.24" actuatorfrcrange="-18 18"/>
        <geom size="0.032 0.035" pos="0.063 0 0" type="cylinder" rgba="0.15 0.15 0.15 1"/>
        <geom size="0.045 0.05 0.03" pos="0.055 0 -0.064" type="box" rgba="0.15 0.15 0.15 1"/>
        <body name="waist_yaw_link" pos="0.0635 0 0">
          <inertial pos="0.093599 0.001858 -0.063897" quat="0.945335 -0.0296492 -0.324416 -0.0147147" mass="1.264" diaginertia="0.00327316 0.00300604 0.00124853"/>
          <joint name="waist_yaw_joint" pos="0 0 0" axis="0 -0.001365 0.999999" range="-1.2 1.2" actuatorfrcrange="-18 18"/>
          <geom size="0.031 0.034" pos="0.063111 0.00241 -0.02386" quat="0.707107 0.707107 0 0" type="cylinder" rgba="0.898039 0.917647 0.929412 1"/>
          <geom size="0.04 0.044" pos="0.111 -1e-05 -0.086" quat="0.707107 0.707107 0 0" type="cylinder" rgba="0.898039 0.917647 0.929412 1"/>
          <body name="neck_pitch_link" pos="0.063536 0 -0.022505">
            <inertial pos="0.045423 0.003582 0.028868" quat="0.124037 0.465653 -0.22472 0.846926" mass="0.295" diaginertia="0.000196492 0.00018447 0.000107427"/>
            <joint name="neck_pitch_joint" pos="0 0 0" axis="0 1 0" range="-0.58 0.45" actuatorfrcrange="-18 18"/>
            <geom size="0.028 0.025" pos="0.047501 0.002934 0.028889" quat="-0.481665 0 0.876356 0" type="cylinder" rgba="0.898039 0.917647 0.929412 1"/>
            <body name="head_roll_link" pos="0.067501 0 0.042889" quat="0.960265 0 -0.279089 0">
              <inertial pos="0.024598 -0.000903 -0.004933" quat="0.694758 0.0263329 -0.00375877 0.718752" mass="0.274" diaginertia="0.000114143 0.000110725 0.000100901"/>
              <joint name="head_roll_joint" pos="0 0 0" axis="-1 0.00073162 0" range="-3.14159 3.14159" actuatorfrcrange="-6 6"/>
              <geom size="0.026 0.025" pos="0.026 -0.001066 -0.01" type="cylinder" rgba="0.898039 0.917647 0.929412 1"/>
              <body name="head_yaw_link" pos="0.025514 0 0.016495">
                <inertial pos="0.000375 0.003846 0.025048" quat="0.726868 0.686501 0.00709524 0.0181354" mass="0.274" diaginertia="0.000114069 0.000110772 0.000100838"/>
                <joint name="head_yaw_joint" pos="0 0 0" axis="0 0 1" range="-3.14159 3.14159" actuatorfrcrange="-6 6"/>
                <geom size="0.025 0.03" pos="0 0.004947 0.025" quat="0.707107 0.707107 0 0" type="cylinder" rgba="0.898039 0.917647 0.929412 1"/>
                <body name="head_pitch_link" pos="0.000471737 0 0.0259972" quat="0.960264 0 0.279094 0">
                  <inertial pos="0.007085 -0.015964 0.010022" quat="0.63184 0.131289 0.317355 0.694857" mass="0.025" diaginertia="8.68475e-06 7.84504e-06 2.62422e-06"/>
                  <joint name="head_pitch_joint" pos="0 0 0" axis="0 1 0" range="-1.7 0.5" actuatorfrcrange="-6 6"/>
                  <geom size="0.04 0.06" pos="0.05 -0.007584 0.05" quat="0.531919 0 0.846795 0" type="cylinder" rgba="0.898039 0.917647 0.929412 1"/>
                </body>
              </body>
            </body>
          </body>
          <body name="fl_hip_pitch_link" pos="0.11134 0.040867 -0.085936">
            <inertial pos="-0.036249 0.026759 -0.000895" quat="0.135919 0.695751 -0.0968273 0.698628" mass="0.266" diaginertia="0.000125848 0.000122921 9.14815e-05"/>
            <joint name="fl_hip_pitch_joint" pos="0 0 0" axis="0 0.999999 0.001365" range="-3.14159 0.97" actuatorfrcrange="-17 17"/>
            <geom size="0.025 0.0315" pos="-0.036 0.027077 0" quat="0.707107 0 0.707107 0" type="cylinder" rgba="0.898039 0.917647 0.929412 1"/>
            <body name="fl_thigh_roll_link" pos="-0.0205 0.028 3.8219e-05">
              <inertial pos="0.019147 0.004421 -0.030852" quat="0.78983 0.00226356 -0.138004 0.597594" mass="0.087" diaginertia="7.84357e-05 7.75876e-05 8.73069e-06"/>
              <joint name="fl_thigh_roll_joint" pos="0 0 0" axis="0.999655 3.58418e-05 0.0262579" range="-0.18 3.14159" actuatorfrcrange="-6 6"/>
              <geom size="0.0025 0.0175 0.03" pos="0.0218 0.002 -0.017" type="box" rgba="0.898039 0.917647 0.929412 1"/>
              <body name="fl_calf_link" pos="0.0235 0.0034955 -0.069995">
                <inertial pos="0.001263 -0.01232 -0.030292" quat="0.998586 0.0482594 -0.0213329 -0.00646046" mass="0.462" diaginertia="0.000781866 0.000763652 0.000131638"/>
                <joint name="fl_calf_joint" pos="0 0 0" axis="0 0.999999 0.001365" range="-1.82 1.93" actuatorfrcrange="-6 6"/>
                <geom size="0.016 0.036" pos="0.00202 -0.008517 -0.06097" type="cylinder" rgba="0.898039 0.917647 0.929412 1"/>
                <geom size="0.023 0.0285" pos="0.00202 -0.014117 0" quat="0.707107 0.707107 0 0" type="cylinder" rgba="0.898039 0.917647 0.929412 1"/>
                <body name="fl_tarsus_link" pos="0.0040403 -0.0022336 -0.12194">
                  <inertial pos="0.000367284 -0.00108794 -0.0246026" quat="0.441484 0.896428 -0.0333619 -0.0198941" mass="0.072" diaginertia="3.68369e-05 3.02974e-05 1.2846e-05"/>
                  <joint name="fl_tarsus_joint" pos="0 0 0" axis="0 0.999999 0.001365" range="-1.49 0.03" actuatorfrcrange="-0.4119 0.4119"/>
                  <geom size="0.018 0.026" pos="0 -0.003725 -0.020974" type="cylinder" rgba="0.898039 0.917647 0.929412 1"/>
                  <geom pos="0 -0.005449 -0.051948" quat="1 0 0 0" type="mesh" rgba="0.898039 0.917647 0.929412 1" mesh="fl_foot_link"/>
                </body>
              </body>
            </body>
          </body>
          <body name="fr_hip_pitch_link" pos="0.11134 -0.040633 -0.086047">
            <inertial pos="-0.036249 -0.026759 -0.000895" quat="-0.135919 0.695751 0.0968273 0.698628" mass="0.266" diaginertia="0.000125848 0.000122921 9.14815e-05"/>
            <joint name="fr_hip_pitch_joint" pos="0 0 0" axis="0 -0.999999 -0.001365" range="-0.97 3.14159" actuatorfrcrange="-17 17"/>
            <geom size="0.025 0.0315" pos="-0.036 -0.027077 0" quat="0.707107 0 0.707107 0" type="cylinder" rgba="0.898039 0.917647 0.929412 1"/>
            <body name="fr_thigh_roll_link" pos="-0.020493 -0.027999 -0.00057652">
              <inertial pos="0.019147 -0.004421 -0.030852" quat="0.597594 -0.138004 0.00226356 0.78983" mass="0.087" diaginertia="7.84357e-05 7.75876e-05 8.73069e-06"/>
              <joint name="fr_thigh_roll_joint" pos="0 0 0" axis="0.999655 -3.58418e-05 0.0262579" range="-3.14159 0.18" actuatorfrcrange="-6 6"/>
              <geom size="0.0025 0.0175 0.03" pos="0.0218 -0.002 -0.017" type="box" rgba="0.898039 0.917647 0.929412 1"/>
              <body name="fr_calf_link" pos="0.02533 -0.0033053 -0.069363">
                <inertial pos="0.001263 0.01232 -0.030292" quat="0.998586 -0.0482594 -0.0213329 0.00646046" mass="0.462" diaginertia="0.000781866 0.000763652 0.000131638"/>
                <joint name="fr_calf_joint" pos="0 0 0" axis="0 -0.999999 -0.001365" range="-1.93 1.82" actuatorfrcrange="-6 6"/>
                <geom size="0.016 0.036" pos="0.00202 0.008517 -0.06097" type="cylinder" rgba="0.898039 0.917647 0.929412 1"/>
                <geom size="0.023 0.0285" pos="0.00202 0.014117 0" quat="0.707107 0.707107 0 0" type="cylinder" rgba="0.898039 0.917647 0.929412 1"/>
                <body name="fr_tarsus_link" pos="0.0055464 0.0025664 -0.12187">
                  <inertial pos="-0.000376842 0.0083019 -0.0247871" quat="0.388365 0.920427 0.0371444 0.0246465" mass="0.072" diaginertia="3.12629e-05 2.39544e-05 1.36257e-05"/>
                  <joint name="fr_tarsus_joint" pos="0 0 0" axis="0 -0.999999 -0.001365" range="-0.03 1.49" actuatorfrcrange="-0.4119 0.4119"/>
                  <geom size="0.018 0.026" pos="0 0.003795 -0.020967" type="cylinder" rgba="0.898039 0.917647 0.929412 1"/>
                  <geom pos="0 0.0055908 -0.051933" quat="1 0 0 0" type="mesh" rgba="0.898039 0.917647 0.929412 1" mesh="fr_foot_link"/>
                </body>
              </body>
            </body>
          </body>
        </body>
      </body>
    </body>
    </body>
  </worldbody>
</mujoco>
